Workbook

Sheet period
A1: Date | B1: Year | C1: Month | D1: Period | E1: Periods | F1: Code | G1: Product | H1: Export_Tons | I1: Export_USD_k | J1: Import_Tons | K1: Import_USD_k | L1: Balance_USD_k
A2: 45536 | B2: 2024 | C2: 9 | D2: січень-вересень | E2: Січ.-вер. 2024 | F2: 102 | G2: ВРХ | H2: 10451 | I2: 19249.9 | J2: 469.8 | K2: 2988.7 | L2: =I2-K2 -> 16261.2
A3: 45536 | B3: 2024 | C3: 9 | D3: січень-вересень | E3: Січ.-вер. 2024 | F3: 201 | G3: М'ясо ВРХ охолоджене | H3: 886.8 | I3: 5566.6 | J3: 108 | K3: 2239.5 | L3: =I3-K3 -> 3327.1
A4: 45536 | B4: 2024 | C4: 9 | D4: січень-вересень | E4: Січ.-вер. 2024 | F4: 202 | G4: М'ясо ВРХ морожене | H4: 12567.9 | I4: 50841.7 | J4: 1925 | K4: 10163.7 | L4: =I4-K4 -> 40678
A5: 45870 | B5: 2025 | C5: 8 | D5: січень-серпень | E5: Січ.-сер. 2025 | F5: 102 | G5: ВРХ | H5: 12724 | I5: 28436 | J5: 512 | K5: 3952 | L5: =I5-K5 -> 24484
A6: 45870 | B6: 2025 | C6: 8 | D6: січень-серпень | E6: Січ.-сер. 2025 | F6: 201 | G6: М'ясо ВРХ охолоджене | H6: 120 | I6: 692 | J6: 95 | K6: 2242 | L6: =I6-K6 -> -1550
A7: 45870 | B7: 2025 | C7: 8 | D7: січень-серпень | E7: Січ.-сер. 2025 | F7: 202 | G7: М'ясо ВРХ морожене | H7: 12631 | I7: 51337 | J7: 1002 | K7: 7518 | L7: =I7-K7 -> 43819
A8: 45901 | B8: 2025 | C8: 9 | D8: січень-вересень | E8: Січ.-вер. 2025 | F8: 102 | G8: ВРХ | H8: 13282 | I8: 29218 | J8: 512 | K8: 3952 | L8: =I8-K8 -> 25266
A9: 45901 | B9: 2025 | C9: 9 | D9: січень-вересень | E9: Січ.-вер. 2025 | F9: 201 | G9: М'ясо ВРХ охолоджене | H9: 224 | I9: 1313 | J9: 106 | K9: 2445 | L9: =I9-K9 -> -1132
A10: 45901 | B10: 2025 | C10: 9 | D10: січень-вересень | E10: Січ.-вер. 2025 | F10: 202 | G10: М'ясо ВРХ морожене | H10: 13805 | I10: 56788 | J10: 1074 | K10: 8194 | L10: =I10-K10 -> 48594
A11: 45901 | B11: 2025 | C11: 9 | D11: січень-вересень | E11: Січ.-вер. 2025 | F11: 401 | G11: Молоко та вершки, не згущені | H11: 14775 | I11: 11882 | J11: 2317 | K11: 3644 | L11: =I11-K11 -> 8238
A12: 45901 | B12: 2025 | C12: 9 | D12: січень-вересень | E12: Січ.-вер. 2025 | F12: 402 | G12: Молоко та вершки, згущені | H12: 28710 | I12: 73683 | J12: 1428 | K12: 5385 | L12: =I12-K12 -> 68298
A13: 45901 | B13: 2025 | C13: 9 | D13: січень-вересень | E13: Січ.-вер. 2025 | F13: 403 | G13: Кисломолочні продукти | H13: 4476 | I13: 6641 | J13: 6811 | K13: 14365 | L13: =I13-K13 -> -7724
... A320: 46266 | B320: 2026 | C320: 9 | D320: січень-вересень | E320: Січ.-вер. 2026 | F320: 3501 | G320: Казеїн | H320: 3061 | I320: 20400 | J320: 92 | K320: 614 | L320: =I320-K320 -> 19786

Sheet monthly
A1: Date | B1: Year | C1: Month | D1: Period | E1: Month2 | F1: Code | G1: Product | H1: Export_Tons | I1: Export_USD_k | J1: Import_Tons | K1: Import_USD_k | L1: Balance_USD_k | M1: Month_1
A2: 45536 | B2: 2024 | C2: 9 | D2: вересень | E2: 45536 | F2: 102 | G2: ВРХ | H2: 2076 | I2: 4430.9 | J2: 53.8 | K2: 436.7 | L2: =I2-K2 -> 3994.2
A3: 45536 | B3: 2024 | C3: 9 | D3: вересень | E3: 45536 | F3: 201 | G3: М'ясо ВРХ охолоджене | H3: 0.8 | I3: 10.6 | J3: 19 | K3: 358.5 | L3: =I3-K3 -> -347.9
A4: 45536 | B4: 2024 | C4: 9 | D4: вересень | E4: 45536 | F4: 202 | G4: М'ясо ВРХ морожене | H4: 1589.9 | I4: 6136.7 | J4: 224 | K4: 1185.7 | L4: =I4-K4 -> 4951
A5: 45870 | B5: 2025 | C5: 8 | D5: серпень | E5: 45870 | F5: 102 | G5: ВРХ | H5: 1011 | I5: 2781 | J5: 18 | K5: 131 | L5: =I5-K5 -> 2650
A6: 45870 | B6: 2025 | C6: 8 | D6: серпень | E6: 45870 | F6: 201 | G6: М'ясо ВРХ охолоджене | H6: 19 | I6: 105 | J6: 15 | K6: 425 | L6: =I6-K6 -> -320
A7: 45870 | B7: 2025 | C7: 8 | D7: серпень | E7: 45870 | F7: 202 | G7: М'ясо ВРХ морожене | H7: 1356 | I7: 6193 | J7: 61 | K7: 528 | L7: =I7-K7 -> 5665
A8: 45901 | B8: 2025 | C8: 9 | D8: вересень | E8: 45901 | F8: 102 | G8: ВРХ | H8: 558 | I8: 782 | J8: 0 | K8: 0 | L8: =I8-K8 -> 782
A9: 45901 | B9: 2025 | C9: 9 | D9: вересень | E9: 45901 | F9: 201 | G9: М'ясо ВРХ охолоджене | H9: 104 | I9: 621 | J9: 11 | K9: 203 | L9: =I9-K9 -> 418
A10: 45901 | B10: 2025 | C10: 9 | D10: вересень | E10: 45901 | F10: 202 | G10: М'ясо ВРХ морожене | H10: 1174 | I10: 5451 | J10: 72 | K10: 676 | L10: =I10-K10 -> 4775
A11: 45901 | B11: 2025 | C11: 9 | D11: вересень | E11: 45901 | F11: 401 | G11: Молоко та вершки, не згущені | H11: 2079 | I11: 1709 | J11: 554 | K11: 676 | L11: =I11-K11 -> 1033
A12: 45901 | B12: 2025 | C12: 9 | D12: вересень | E12: 45901 | F12: 402 | G12: Молоко та вершки, згущені | H12: 1816 | I12: 4560 | J12: 266 | K12: 1198 | L12: =I12-K12 -> 3362
A13: 45901 | B13: 2025 | C13: 9 | D13: вересень | E13: 45901 | F13: 403 | G13: Кисломолочні продукти | H13: 580 | I13: 936 | J13: 632 | K13: 1435 | L13: =I13-K13 -> -499
... A290: 46266 | B290: 2026 | C290: 9 | D290: вересень | E290: 46266 | F290: 3501 | G290: Казеїн | H290: 249 | I290: 1797 | J290: 1 | K290: 8 | L290: =I290-K290 -> 1789

Sheet country
A1: country | B1: flow | C1: metrics | D1: value
A2: Лівія | D2: 702
A3: Саудівська Аравія | D3: 714
A4: Йорданія | D4: 786
A5: Казахстан | D5: 1179
A6: Ліван | D6: 31869

Sheet country dairy
A1: country | B1: flow | C1: metrics | D1: value
A2: Грузія | D2: 7232
A3: Литва | D3: 8069
A4: США | D4: 8324
A5: Азербайджан | D5: 9030
A6: Ізраїль | D6: 12402
A7: Казахстан | D7: 13897
A8: Болгарія | D8: 14792
A9: Німеччина | D9: 32992
A10: Польща | D10: 37258
A11: Молдова | D11: 66812

Sheet dairy
B1: ЕКСПОРТ
B2: тонн | C2: поточна | D2: попередня | E2: мин. рік | J2: тис. дол.
A3: Code | B3: Product | C3: 46266 | D3: 46235 | E3: 45901 | F3: 26/26 | G3: 26/25 | I3: Code | J3: Product | K3: =C$3 -> 46266 | L3: =D$3 -> 46235 | M3: =E$3 -> 45901 | N3: =F$3 -> 26/26 | O3: =G$3 -> 26/25 | R3: Export share
A4: 401 | B4: Молоко та вершки, не згущені | C4: {=INDEX(monthly!$H$2:$H$5025, MATCH(1, (monthly!$E$2:$E$5025=$C$3)* (monthly!$F$2:$F$5025=$A4), 0))} -> 2577 | D4: {=INDEX(monthly!$H$2:$H$5025, MATCH(1, (monthly!$E$2:$E$5025=$D$3)* (monthly!$F$2:$F$5025=$A4), 0))} -> 1798 | E4: {=INDEX(monthly!$H$2:$H$5025, MATCH(1, (monthly!$E$2:$E$5025=$E$3)* (monthly!$F$2:$F$5025=$A4), 0))} -> 2079 | F4: =IFERROR((C4/D4)-1,0) -> 0.43325918 | G4: =IFERROR((C4/E4)-1,0) -> 0.23953824 | I4: 401 | J4: Молоко та вершки, не згущені | K4: {=INDEX(monthly!$I$2:$I$5025, MATCH(1, (monthly!$E$2:$E$5025=$K$3)* (monthly!$F$2:$F$5025=$I4), 0))} -> 2057 | L4: {=INDEX(monthly!$I$2:$I$5025, MATCH(1, (monthly!$E$2:$E$5025=$L$3)* (monthly!$F$2:$F$5025=$I4), 0))} -> 1510 | M4: {=INDEX(monthly!$I$2:$I$5025, MATCH(1, (monthly!$E$2:$E$5025=$M$3)* (monthly!$F$2:$F$5025=$I4), 0))} -> 1709 | N4: =IFERROR((K4/L4)-1,0) -> 0.36225166 | O4: =IFERROR((K4/M4)-1,0) -> 0.20362785 | Q4: Молоко та вершки, не згущені | R4: =K4/$K$12*100% -> 0.065167115
A5: 402 | B5: Молоко та вершки, згущені | C5: {=INDEX(monthly!$H$2:$H$5025, MATCH(1, (monthly!$E$2:$E$5025=$C$3)* (monthly!$F$2:$F$5025=$A5), 0))} -> 3391 | D5: {=INDEX(monthly!$H$2:$H$5025, MATCH(1, (monthly!$E$2:$E$5025=$D$3)* (monthly!$F$2:$F$5025=$A5), 0))} -> 2761 | E5: {=INDEX(monthly!$H$2:$H$5025, MATCH(1, (monthly!$E$2:$E$5025=$E$3)* (monthly!$F$2:$F$5025=$A5), 0))} -> 1816 | F5: =IFERROR((C5/D5)-1,0) -> 0.2281782 | G5: =IFERROR((C5/E5)-1,0) -> 0.86729075 | I5: 402 | J5: Молоко та вершки, згущені | K5: {=INDEX(monthly!$I$2:$I$5025, MATCH(1, (monthly!$E$2:$E$5025=$K$3)* (monthly!$F$2:$F$5025=$I5), 0))} -> 9842 | L5: {=INDEX(monthly!$I$2:$I$5025, MATCH(1, (monthly!$E$2:$E$5025=$L$3)* (monthly!$F$2:$F$5025=$I5), 0))} -> 7759 | M5: {=INDEX(monthly!$I$2:$I$5025, MATCH(1, (monthly!$E$2:$E$5025=$M$3)* (monthly!$F$2:$F$5025=$I5), 0))} -> 4560 | N5: =IFERROR((K5/L5)-1,0) -> 0.26846243 | O5: =IFERROR((K5/M5)-1,0) -> 1.1583333 | Q5: Молоко та вершки, згущені | R5: =K5/$K$12*100% -> 0.31180105
A6: 403 | B6: Кисломолочні продукти | C6: {=INDEX(monthly!$H$2:$H$5025, MATCH(1, (monthly!$E$2:$E$5025=$C$3)* (monthly!$F$2:$F$5025=$A6), 0))} -> 647 | D6: {=INDEX(monthly!$H$2:$H$5025, MATCH(1, (monthly!$E$2:$E$5025=$D$3)* (monthly!$F$2:$F$5025=$A6), 0))} -> 734 | E6: {=INDEX(monthly!$H$2:$H$5025, MATCH(1, (monthly!$E$2:$E$5025=$E$3)* (monthly!$F$2:$F$5025=$A6), 0))} -> 580 | F6: =IFERROR((C6/D6)-1,0) -> -0.11852861 | G6: =IFERROR((C6/E6)-1,0) -> 0.11551724 | I6: 403 | J6: Кисломолочні продукти | K6: {=INDEX(monthly!$I$2:$I$5025, MATCH(1, (monthly!$E$2:$E$5025=$K$3)* (monthly!$F$2:$F$5025=$I6), 0))} -> 929 | L6: {=INDEX(monthly!$I$2:$I$5025, MATCH(1, (monthly!$E$2:$E$5025=$L$3)* (monthly!$F$2:$F$5025=$I6), 0))} -> 1073 | M6: {=INDEX(monthly!$I$2:$I$5025, MATCH(1, (monthly!$E$2:$E$5025=$M$3)* (monthly!$F$2:$F$5025=$I6), 0))} -> 936 | N6: =IFERROR((K6/L6)-1,0) -> -0.13420317 | O6: =IFERROR((K6/M6)-1,0) -> -0.0074786325 | Q6: Маслянка | R6: =K6/$K$12*100% -> 0.029431332
A7: 404 | B7: Молочна сироватка | C7: {=INDEX(monthly!$H$2:$H$5025, MATCH(1, (monthly!$E$2:$E$5025=$C$3)* (monthly!$F$2:$F$5025=$A7), 0))} -> 1576 | D7: {=INDEX(monthly!$H$2:$H$5025, MATCH(1, (monthly!$E$2:$E$5025=$D$3)* (monthly!$F$2:$F$5025=$A7), 0))} -> 1359 | E7: {=INDEX(monthly!$H$2:$H$5025, MATCH(1, (monthly!$E$2:$E$5025=$E$3)* (monthly!$F$2:$F$5025=$A7), 0))} -> 1051 | F7: =IFERROR((C7/D7)-1,0) -> 0.15967623 | G7: =IFERROR((C7/E7)-1,0) -> 0.49952426 | I7: 404 | J7: Молочна сироватка | K7: {=INDEX(monthly!$I$2:$I$5025, MATCH(1, (monthly!$E$2:$E$5025=$K$3)* (monthly!$F$2:$F$5025=$I7), 0))} -> 2607 | L7: {=INDEX(monthly!$I$2:$I$5025, MATCH(1, (monthly!$E$2:$E$5025=$L$3)* (monthly!$F$2:$F$5025=$I7), 0))} -> 2241 | M7: {=INDEX(monthly!$I$2:$I$5025, MATCH(1, (monthly!$E$2:$E$5025=$M$3)* (monthly!$F$2:$F$5025=$I7), 0))} -> 1136 | N7: =IFERROR((K7/L7)-1,0) -> 0.16331995 | O7: =IFERROR((K7/M7)-1,0) -> 1.2948944 | Q7: Молочна сироватка | R7: =K7/$K$12*100% -> 0.082591478
A8: 405 | B8: Масло вершкове | C8: {=INDEX(monthly!$H$2:$H$5025, MATCH(1, (monthly!$E$2:$E$5025=$C$3)* (monthly!$F$2:$F$5025=$A8), 0))} -> 782 | D8: {=INDEX(monthly!$H$2:$H$5025, MATCH(1, (monthly!$E$2:$E$5025=$D$3)* (monthly!$F$2:$F$5025=$A8), 0))} -> 622 | E8: {=INDEX(monthly!$H$2:$H$5025, MATCH(1, (monthly!$E$2:$E$5025=$E$3)* (monthly!$F$2:$F$5025=$A8), 0))} -> 916 | F8: =IFERROR((C8/D8)-1,0) -> 0.25723473 | G8: =IFERROR((C8/E8)-1,0) -> -0.14628821 | I8: 405 | J8: Масло вершкове | K8: {=INDEX(monthly!$I$2:$I$5025, MATCH(1, (monthly!$E$2:$E$5025=$K$3)* (monthly!$F$2:$F$5025=$I8), 0))} -> 4102 | L8: {=INDEX(monthly!$I$2:$I$5025, MATCH(1, (monthly!$E$2:$E$5025=$L$3)* (monthly!$F$2:$F$5025=$I8), 0))} -> 3270 | M8: {=INDEX(monthly!$I$2:$I$5025, MATCH(1, (monthly!$E$2:$E$5025=$M$3)* (monthly!$F$2:$F$5025=$I8), 0))} -> 6855 | N8: =IFERROR((K8/L8)-1,0) -> 0.25443425 | O8: =IFERROR((K8/M8)-1,0) -> -0.40160467 | Q8: Масло вершкове | R8: =K8/$K$12*100% -> 0.12995406
A9: 406 | B9: Сири | C9: {=INDEX(monthly!$H$2:$H$5025, MATCH(1, (monthly!$E$2:$E$5025=$C$3)* (monthly!$F$2:$F$5025=$A9), 0))} -> 1512 | D9: {=INDEX(monthly!$H$2:$H$5025, MATCH(1, (monthly!$E$2:$E$5025=$D$3)* (monthly!$F$2:$F$5025=$A9), 0))} -> 1218 | E9: {=INDEX(monthly!$H$2:$H$5025, MATCH(1, (monthly!$E$2:$E$5025=$E$3)* (monthly!$F$2:$F$5025=$A9), 0))} -> 1214 | F9: =IFERROR((C9/D9)-1,0) -> 0.24137931 | G9: =IFERROR((C9/E9)-1,0) -> 0.24546952 | I9: 406 | J9: Сири | K9: {=INDEX(monthly!$I$2:$I$5025, MATCH(1, (monthly!$E$2:$E$5025=$K$3)* (monthly!$F$2:$F$5025=$I9), 0))} -> 7250 | L9: {=INDEX(monthly!$I$2:$I$5025, MATCH(1, (monthly!$E$2:$E$5025=$L$3)* (monthly!$F$2:$F$5025=$I9), 0))} -> 5246 | M9: {=INDEX(monthly!$I$2:$I$5025, MATCH(1, (monthly!$E$2:$E$5025=$M$3)* (monthly!$F$2:$F$5025=$I9), 0))} -> 5465 | N9: =IFERROR((K9/L9)-1,0) -> 0.38200534 | O9: =IFERROR((K9/M9)-1,0) -> 0.32662397 | Q9: Сири | R9: =K9/$K$12*100% -> 0.22968478
A10: 2105 | B10: Морозиво | C10: {=INDEX(monthly!$H$2:$H$5025, MATCH(1, (monthly!$E$2:$E$5025=$C$3)* (monthly!$F$2:$F$5025=$A10), 0))} -> 719 | D10: {=INDEX(monthly!$H$2:$H$5025, MATCH(1, (monthly!$E$2:$E$5025=$D$3)* (monthly!$F$2:$F$5025=$A10), 0))} -> 2170 | E10: {=INDEX(monthly!$H$2:$H$5025, MATCH(1, (monthly!$E$2:$E$5025=$E$3)* (monthly!$F$2:$F$5025=$A10), 0))} -> 690 | F10: =IFERROR((C10/D10)-1,0) -> -0.66866359 | G10: =IFERROR((C10/E10)-1,0) -> 0.042028986 | I10: 2105 | J10: Морозиво | K10: {=INDEX(monthly!$I$2:$I$5025, MATCH(1, (monthly!$E$2:$E$5025=$K$3)* (monthly!$F$2:$F$5025=$I10), 0))} -> 2981 | L10: {=INDEX(monthly!$I$2:$I$5025, MATCH(1, (monthly!$E$2:$E$5025=$L$3)* (monthly!$F$2:$F$5025=$I10), 0))} -> 7963 | M10: {=INDEX(monthly!$I$2:$I$5025, MATCH(1, (monthly!$E$2:$E$5025=$M$3)* (monthly!$F$2:$F$5025=$I10), 0))} -> 2601 | N10: =IFERROR((K10/L10)-1,0) -> -0.6256436 | O10: =IFERROR((K10/M10)-1,0) -> 0.14609765 | Q10: Морозиво | R10: =K10/$K$12*100% -> 0.094440044
A11: 3501 | B11: Казеїн | C11: {=INDEX(monthly!$H$2:$H$5025, MATCH(1, (monthly!$E$2:$E$5025=$C$3)* (monthly!$F$2:$F$5025=$A11), 0))} -> 249 | D11: {=INDEX(monthly!$H$2:$H$5025, MATCH(1, (monthly!$E$2:$E$5025=$D$3)* (monthly!$F$2:$F$5025=$A11), 0))} -> 207 | E11: {=INDEX(monthly!$H$2:$H$5025, MATCH(1, (monthly!$E$2:$E$5025=$E$3)* (monthly!$F$2:$F$5025=$A11), 0))} -> 307 | F11: =IFERROR((C11/D11)-1,0) -> 0.20289855 | G11: =IFERROR((C11/E11)-1,0) -> -0.18892508 | I11: 3501 | J11: Казеїн | K11: {=INDEX(monthly!$I$2:$I$5025, MATCH(1, (monthly!$E$2:$E$5025=$K$3)* (monthly!$F$2:$F$5025=$I11), 0))} -> 1797 | L11: {=INDEX(monthly!$I$2:$I$5025, MATCH(1, (monthly!$E$2:$E$5025=$L$3)* (monthly!$F$2:$F$5025=$I11), 0))} -> 1456 | M11: {=INDEX(monthly!$I$2:$I$5025, MATCH(1, (monthly!$E$2:$E$5025=$M$3)* (monthly!$F$2:$F$5025=$I11), 0))} -> 1873 | N11: =IFERROR((K11/L11)-1,0) -> 0.2342033 | O11: =IFERROR((K11/M11)-1,0) -> -0.040576615 | Q11: Казеїн | R11: =K11/$K$12*100% -> 0.056930144
C12: =SUM(C4:C11) -> 11453 | D12: =SUM(D4:D11) -> 10869 | E12: =SUM(E4:E11) -> 8653 | F12: =IFERROR((C12/D12)-1,0) -> 0.053730794 | G12: =IFERROR((C12/E12)-1,0) -> 0.3235872 | K12: =SUM(K4:K11) -> 31565 | L12: =SUM(L4:L11) -> 30518 | M12: =SUM(M4:M11) -> 25135 | N12: =IFERROR((K12/L12)-1,0) -> 0.034307622 | O12: =IFERROR((K12/M12)-1,0) -> 0.25581858 | R12: =SUM(R4:R11) -> 1
B15: З поч. року | J15: З поч. року
B16: тонн | C16: поточна | D16: попередня | E16: мин. рік | J16: тис. дол.
A17: Code | B17: Product | C17: Січ.-вер. 2026 | D17: Січ.-сер. 2026 | E17: Січ.-вер. 2025 | F17: =G$3 -> 26/25 | H17: місяць | I17: Code | J17: Product | K17: =C$17 -> Січ.-вер. 2026 | L17: =D$17 -> Січ.-сер. 2026 | M17: =E$17 -> Січ.-вер. 2025 | N17: =G$3 -> 26/25 | P17: місяць
A18: 401 | B18: Молоко та вершки, не згущені | C18: {=INDEX(period!$H$2:$H$5033, MATCH(1, (period!$E$2:$E$5033=$C$17)* (period!$F$2:$F$5033=$A18), 0))} -> 15289 | D18: {=INDEX(period!$H$2:$H$5033, MATCH(1, (period!$E$2:$E$5033=$D$17)* (period!$F$2:$F$5033=$A18), 0))} -> 12712 | E18: {=INDEX(period!$H$2:$H$5033, MATCH(1, (period!$E$2:$E$5033=$E$17)* (period!$F$2:$F$5033=$A18), 0))} -> 14775 | F18: =(C18/E18)-1 -> 0.034788494 | H18: =C18-D18 -> 2577 | I18: 401 | J18: Молоко та вершки, не згущені | K18: {=INDEX(period!$I$2:$I$5033, MATCH(1, (period!$E$2:$E$5033=$K$17)* (period!$F$2:$F$5033=$I18), 0))} -> 13222 | L18: {=INDEX(period!$I$2:$I$5033, MATCH(1, (period!$E$2:$E$5033=$L$17)* (period!$F$2:$F$5033=$I18), 0))} -> 11165 | M18: {=INDEX(period!$I$2:$I$5033, MATCH(1, (period!$E$2:$E$5033=$M$17)* (period!$F$2:$F$5033=$I18), 0))} -> 11882 | N18: =(K18/M18)-1 -> 0.11277563 | P18: =K18-L18 -> 2057
A19: 402 | B19: Молоко та вершки, згущені | C19: {=INDEX(period!$H$2:$H$5033, MATCH(1, (period!$E$2:$E$5033=$C$17)* (period!$F$2:$F$5033=$A19), 0))} -> 28354 | D19: {=INDEX(period!$H$2:$H$5033, MATCH(1, (period!$E$2:$E$5033=$D$17)* (period!$F$2:$F$5033=$A19), 0))} -> 24963 | E19: {=INDEX(period!$H$2:$H$5033, MATCH(1, (period!$E$2:$E$5033=$E$17)* (period!$F$2:$F$5033=$A19), 0))} -> 28710 | F19: =(C19/E19)-1 -> -0.012399861 | H19: =C19-D19 -> 3391 | I19: 402 | J19: Молоко та вершки, згущені | K19: {=INDEX(period!$I$2:$I$5033, MATCH(1, (period!$E$2:$E$5033=$K$17)* (period!$F$2:$F$5033=$I19), 0))} -> 76035 | L19: {=INDEX(period!$I$2:$I$5033, MATCH(1, (period!$E$2:$E$5033=$L$17)* (period!$F$2:$F$5033=$I19), 0))} -> 66193 | M19: {=INDEX(period!$I$2:$I$5033, MATCH(1, (period!$E$2:$E$5033=$M$17)* (period!$F$2:$F$5033=$I19), 0))} -> 73683 | N19: =(K19/M19)-1 -> 0.031920524 | P19: =K19-L19 -> 9842
A20: 403 | B20: Кисломолочні продукти | C20: {=INDEX(period!$H$2:$H$5033, MATCH(1, (period!$E$2:$E$5033=$C$17)* (period!$F$2:$F$5033=$A20), 0))} -> 5620 | D20: {=INDEX(period!$H$2:$H$5033, MATCH(1, (period!$E$2:$E$5033=$D$17)* (period!$F$2:$F$5033=$A20), 0))} -> 4973 | E20: {=INDEX(period!$H$2:$H$5033, MATCH(1, (period!$E$2:$E$5033=$E$17)* (period!$F$2:$F$5033=$A20), 0))} -> 4476 | F20: =(C20/E20)-1 -> 0.25558534 | H20: =C20-D20 -> 647 | I20: 403 | J20: Кисломолочні продукти | K20: {=INDEX(period!$I$2:$I$5033, MATCH(1, (period!$E$2:$E$5033=$K$17)* (period!$F$2:$F$5033=$I20), 0))} -> 8284 | L20: {=INDEX(period!$I$2:$I$5033, MATCH(1, (period!$E$2:$E$5033=$L$17)* (period!$F$2:$F$5033=$I20), 0))} -> 7355 | M20: {=INDEX(period!$I$2:$I$5033, MATCH(1, (period!$E$2:$E$5033=$M$17)* (period!$F$2:$F$5033=$I20), 0))} -> 6641 | N20: =(K20/M20)-1 -> 0.2474025 | P20: =K20-L20 -> 929
A21: 404 | B21: Молочна сироватка | C21: {=INDEX(period!$H$2:$H$5033, MATCH(1, (period!$E$2:$E$5033=$C$17)* (period!$F$2:$F$5033=$A21), 0))} -> 13151 | D21: {=INDEX(period!$H$2:$H$5033, MATCH(1, (period!$E$2:$E$5033=$D$17)* (period!$F$2:$F$5033=$A21), 0))} -> 11575 | E21: {=INDEX(period!$H$2:$H$5033, MATCH(1, (period!$E$2:$E$5033=$E$17)* (period!$F$2:$F$5033=$A21), 0))} -> 12498 | F21: =(C21/E21)-1 -> 0.05224836 | H21: =C21-D21 -> 1576 | I21: 404 | J21: Молочна сироватка | K21: {=INDEX(period!$I$2:$I$5033, MATCH(1, (period!$E$2:$E$5033=$K$17)* (period!$F$2:$F$5033=$I21), 0))} -> 18361 | L21: {=INDEX(period!$I$2:$I$5033, MATCH(1, (period!$E$2:$E$5033=$L$17)* (period!$F$2:$F$5033=$I21), 0))} -> 15754 | M21: {=INDEX(period!$I$2:$I$5033, MATCH(1, (period!$E$2:$E$5033=$M$17)* (period!$F$2:$F$5033=$I21), 0))} -> 11969 | N21: =(K21/M21)-1 -> 0.53404629 | P21: =K21-L21 -> 2607
A22: 405 | B22: Масло вершкове | C22: {=INDEX(period!$H$2:$H$5033, MATCH(1, (period!$E$2:$E$5033=$C$17)* (period!$F$2:$F$5033=$A22), 0))} -> 6972 | D22: {=INDEX(period!$H$2:$H$5033, MATCH(1, (period!$E$2:$E$5033=$D$17)* (period!$F$2:$F$5033=$A22), 0))} -> 6190 | E22: {=INDEX(period!$H$2:$H$5033, MATCH(1, (period!$E$2:$E$5033=$E$17)* (period!$F$2:$F$5033=$A22), 0))} -> 12698 | F22: =(C22/E22)-1 -> -0.45093716 | H22: =C22-D22 -> 782 | I22: 405 | J22: Масло вершкове | K22: {=INDEX(period!$I$2:$I$5033, MATCH(1, (period!$E$2:$E$5033=$K$17)* (period!$F$2:$F$5033=$I22), 0))} -> 38494 | L22: {=INDEX(period!$I$2:$I$5033, MATCH(1, (period!$E$2:$E$5033=$L$17)* (period!$F$2:$F$5033=$I22), 0))} -> 34392 | M22: {=INDEX(period!$I$2:$I$5033, MATCH(1, (period!$E$2:$E$5033=$M$17)* (period!$F$2:$F$5033=$I22), 0))} -> 91677 | N22: =(K22/M22)-1 -> -0.58011279 | P22: =K22-L22 -> 4102
A23: 406 | B23: Сири | C23: {=INDEX(period!$H$2:$H$5033, MATCH(1, (period!$E$2:$E$5033=$C$17)* (period!$F$2:$F$5033=$A23), 0))} -> 10942 | D23: {=INDEX(period!$H$2:$H$5033, MATCH(1, (period!$E$2:$E$5033=$D$17)* (period!$F$2:$F$5033=$A23), 0))} -> 9430 | E23: {=INDEX(period!$H$2:$H$5033, MATCH(1, (period!$E$2:$E$5033=$E$17)* (period!$F$2:$F$5033=$A23), 0))} -> 10572 | F23: =(C23/E23)-1 -> 0.034998108 | H23: =C23-D23 -> 1512 | I23: 406 | J23: Сири | K23: {=INDEX(period!$I$2:$I$5033, MATCH(1, (period!$E$2:$E$5033=$K$17)* (period!$F$2:$F$5033=$I23), 0))} -> 49916 | L23: {=INDEX(period!$I$2:$I$5033, MATCH(1, (period!$E$2:$E$5033=$L$17)* (period!$F$2:$F$5033=$I23), 0))} -> 42666 | M23: {=INDEX(period!$I$2:$I$5033, MATCH(1, (period!$E$2:$E$5033=$M$17)* (period!$F$2:$F$5033=$I23), 0))} -> 48275 | N23: =(K23/M23)-1 -> 0.03399275 | P23: =K23-L23 -> 7250
A24: 2105 | B24: Морозиво | C24: {=INDEX(period!$H$2:$H$5033, MATCH(1, (period!$E$2:$E$5033=$C$17)* (period!$F$2:$F$5033=$A24), 0))} -> 14986 | D24: {=INDEX(period!$H$2:$H$5033, MATCH(1, (period!$E$2:$E$5033=$D$17)* (period!$F$2:$F$5033=$A24), 0))} -> 14267 | E24: {=INDEX(period!$H$2:$H$5033, MATCH(1, (period!$E$2:$E$5033=$E$17)* (period!$F$2:$F$5033=$A24), 0))} -> 14169 | F24: =(C24/E24)-1 -> 0.057661091 | H24: =C24-D24 -> 719 | I24: 2105 | J24: Морозиво | K24: {=INDEX(period!$I$2:$I$5033, MATCH(1, (period!$E$2:$E$5033=$K$17)* (period!$F$2:$F$5033=$I24), 0))} -> 55649 | L24: {=INDEX(period!$I$2:$I$5033, MATCH(1, (period!$E$2:$E$5033=$L$17)* (period!$F$2:$F$5033=$I24), 0))} -> 52668 | M24: {=INDEX(period!$I$2:$I$5033, MATCH(1, (period!$E$2:$E$5033=$M$17)* (period!$F$2:$F$5033=$I24), 0))} -> 52098 | N24: =(K24/M24)-1 -> 0.068160006 | P24: =K24-L24 -> 2981
A25: 3501 | B25: Казеїн | C25: {=INDEX(period!$H$2:$H$5033, MATCH(1, (period!$E$2:$E$5033=$C$17)* (period!$F$2:$F$5033=$A25), 0))} -> 3061 | D25: {=INDEX(period!$H$2:$H$5033, MATCH(1, (period!$E$2:$E$5033=$D$17)* (period!$F$2:$F$5033=$A25), 0))} -> 2812 | E25: {=INDEX(period!$H$2:$H$5033, MATCH(1, (period!$E$2:$E$5033=$E$17)* (period!$F$2:$F$5033=$A25), 0))} -> 4255 | F25: =(C25/E25)-1 -> -0.28061105 | H25: =C25-D25 -> 249 | I25: 3501 | J25: Казеїн | K25: {=INDEX(period!$I$2:$I$5033, MATCH(1, (period!$E$2:$E$5033=$K$17)* (period!$F$2:$F$5033=$I25), 0))} -> 20400 | L25: {=INDEX(period!$I$2:$I$5033, MATCH(1, (period!$E$2:$E$5033=$L$17)* (period!$F$2:$F$5033=$I25), 0))} -> 18603 | M25: {=INDEX(period!$I$2:$I$5033, MATCH(1, (period!$E$2:$E$5033=$M$17)* (period!$F$2:$F$5033=$I25), 0))} -> 26976 | N25: =(K25/M25)-1 -> -0.24377224 | P25: =K25-L25 -> 1797
C26: =SUM(C18:C25) -> 98375 | D26: =SUM(D18:D25) -> 86922 | E26: =SUM(E18:E25) -> 102153 | F26: =(C26/E26)-1 -> -0.03698374 | K26: =SUM(K18:K25) -> 280361 | L26: =SUM(L18:L25) -> 248796 | M26: =SUM(M18:M25) -> 323201 | N26: =(K26/M26)-1 -> -0.13254909
B28: ІМПОРТ
B29: тонн | J29: тис. дол.
A30: Code | B30: Product | C30: =C$3 -> 46266 | D30: =D$3 -> 46235 | E30: =E$3 -> 45901 | F30: =F$3 -> 26/26 | G30: =G$3 -> 26/25 | I30: Code | J30: Product | K30: =C$3 -> 46266 | L30: =D$3 -> 46235 | M30: =E$3 -> 45901 | N30: =F$3 -> 26/26 | O30: =G$3 -> 26/25
A31: 401 | B31: Молоко та вершки, не згущені | C31: {=INDEX(monthly!$J$2:$J$5025, MATCH(1, (monthly!$E$2:$E$5025=$C$30)* (monthly!$F$2:$F$5025=$A31), 0))} -> 1277 | D31: {=INDEX(monthly!$J$2:$J$5025, MATCH(1, (monthly!$E$2:$E$5025=$D$30)* (monthly!$F$2:$F$5025=$A31), 0))} -> 1445 | E31: {=INDEX(monthly!$J$2:$J$5025, MATCH(1, (monthly!$E$2:$E$5025=$E$30)* (monthly!$F$2:$F$5025=$A31), 0))} -> 554 | F31: =IFERROR((C31/D31)-1,0) -> -0.11626298 | G31: =IFERROR((C31/E31)-1,0) -> 1.3050542 | I31: 401 | J31: Молоко та вершки, не згущені | K31: {=INDEX(monthly!$K$2:$K$5025, MATCH(1, (monthly!$E$2:$E$5025=$K$30)* (monthly!$F$2:$F$5025=$I31), 0))} -> 1456 | L31: {=INDEX(monthly!$K$2:$K$5025, MATCH(1, (monthly!$E$2:$E$5025=$L$30)* (monthly!$F$2:$F$5025=$I31), 0))} -> 1644 | M31: {=INDEX(monthly!$K$2:$K$5025, MATCH(1, (monthly!$E$2:$E$5025=$M$30)* (monthly!$F$2:$F$5025=$I31), 0))} -> 676 | N31: =IFERROR((K31/L31)-1,0) -> -0.11435523 | O31: =IFERROR((K31/M31)-1,0) -> 1.1538462
A32: 402 | B32: Молоко та вершки, згущені | C32: {=INDEX(monthly!$J$2:$J$5025, MATCH(1, (monthly!$E$2:$E$5025=$C$30)* (monthly!$F$2:$F$5025=$A32), 0))} -> 218 | D32: {=INDEX(monthly!$J$2:$J$5025, MATCH(1, (monthly!$E$2:$E$5025=$D$30)* (monthly!$F$2:$F$5025=$A32), 0))} -> 137 | E32: {=INDEX(monthly!$J$2:$J$5025, MATCH(1, (monthly!$E$2:$E$5025=$E$30)* (monthly!$F$2:$F$5025=$A32), 0))} -> 266 | F32: =IFERROR((C32/D32)-1,0) -> 0.59124088 | G32: =IFERROR((C32/E32)-1,0) -> -0.18045113 | I32: 402 | J32: Молоко та вершки, згущені | K32: {=INDEX(monthly!$K$2:$K$5025, MATCH(1, (monthly!$E$2:$E$5025=$K$30)* (monthly!$F$2:$F$5025=$I32), 0))} -> 859 | L32: {=INDEX(monthly!$K$2:$K$5025, MATCH(1, (monthly!$E$2:$E$5025=$L$30)* (monthly!$F$2:$F$5025=$I32), 0))} -> 542 | M32: {=INDEX(monthly!$K$2:$K$5025, MATCH(1, (monthly!$E$2:$E$5025=$M$30)* (monthly!$F$2:$F$5025=$I32), 0))} -> 1198 | N32: =IFERROR((K32/L32)-1,0) -> 0.58487085 | O32: =IFERROR((K32/M32)-1,0) -> -0.28297162
A33: 403 | B33: Кисломолочні продукти | C33: {=INDEX(monthly!$J$2:$J$5025, MATCH(1, (monthly!$E$2:$E$5025=$C$30)* (monthly!$F$2:$F$5025=$A33), 0))} -> 1034 | D33: {=INDEX(monthly!$J$2:$J$5025, MATCH(1, (monthly!$E$2:$E$5025=$D$30)* (monthly!$F$2:$F$5025=$A33), 0))} -> 959 | E33: {=INDEX(monthly!$J$2:$J$5025, MATCH(1, (monthly!$E$2:$E$5025=$E$30)* (monthly!$F$2:$F$5025=$A33), 0))} -> 632 | F33: =IFERROR((C33/D33)-1,0) -> 0.078206465 | G33: =IFERROR((C33/E33)-1,0) -> 0.63607595 | I33: 403 | J33: Кисломолочні продукти | K33: {=INDEX(monthly!$K$2:$K$5025, MATCH(1, (monthly!$E$2:$E$5025=$K$30)* (monthly!$F$2:$F$5025=$I33), 0))} -> 2211 | L33: {=INDEX(monthly!$K$2:$K$5025, MATCH(1, (monthly!$E$2:$E$5025=$L$30)* (monthly!$F$2:$F$5025=$I33), 0))} -> 2182 | M33: {=INDEX(monthly!$K$2:$K$5025, MATCH(1, (monthly!$E$2:$E$5025=$M$30)* (monthly!$F$2:$F$5025=$I33), 0))} -> 1435 | N33: =IFERROR((K33/L33)-1,0) -> 0.013290559 | O33: =IFERROR((K33/M33)-1,0) -> 0.54076655
A34: 404 | B34: Молочна сироватка | C34: {=INDEX(monthly!$J$2:$J$5025, MATCH(1, (monthly!$E$2:$E$5025=$C$30)* (monthly!$F$2:$F$5025=$A34), 0))} -> 573 | D34: {=INDEX(monthly!$J$2:$J$5025, MATCH(1, (monthly!$E$2:$E$5025=$D$30)* (monthly!$F$2:$F$5025=$A34), 0))} -> 849 | E34: {=INDEX(monthly!$J$2:$J$5025, MATCH(1, (monthly!$E$2:$E$5025=$E$30)* (monthly!$F$2:$F$5025=$A34), 0))} -> 959 | F34: =IFERROR((C34/D34)-1,0) -> -0.32508834 | G34: =IFERROR((C34/E34)-1,0) -> -0.40250261 | I34: 404 | J34: Молочна сироватка | K34: {=INDEX(monthly!$K$2:$K$5025, MATCH(1, (monthly!$E$2:$E$5025=$K$30)* (monthly!$F$2:$F$5025=$I34), 0))} -> 1347 | L34: {=INDEX(monthly!$K$2:$K$5025, MATCH(1, (monthly!$E$2:$E$5025=$L$30)* (monthly!$F$2:$F$5025=$I34), 0))} -> 1862 | M34: {=INDEX(monthly!$K$2:$K$5025, MATCH(1, (monthly!$E$2:$E$5025=$M$30)* (monthly!$F$2:$F$5025=$I34), 0))} -> 1796 | N34: =IFERROR((K34/L34)-1,0) -> -0.27658432 | O34: =IFERROR((K34/M34)-1,0) -> -0.25
A35: 405 | B35: Масло вершкове | C35: {=INDEX(monthly!$J$2:$J$5025, MATCH(1, (monthly!$E$2:$E$5025=$C$30)* (monthly!$F$2:$F$5025=$A35), 0))} -> 199 | D35: {=INDEX(monthly!$J$2:$J$5025, MATCH(1, (monthly!$E$2:$E$5025=$D$30)* (monthly!$F$2:$F$5025=$A35), 0))} -> 243 | E35: {=INDEX(monthly!$J$2:$J$5025, MATCH(1, (monthly!$E$2:$E$5025=$E$30)* (monthly!$F$2:$F$5025=$A35), 0))} -> 246 | F35: =IFERROR((C35/D35)-1,0) -> -0.18106996 | G35: =IFERROR((C35/E35)-1,0) -> -0.19105691 | I35: 405 | J35: Масло вершкове | K35: {=INDEX(monthly!$K$2:$K$5025, MATCH(1, (monthly!$E$2:$E$5025=$K$30)* (monthly!$F$2:$F$5025=$I35), 0))} -> 1157 | L35: {=INDEX(monthly!$K$2:$K$5025, MATCH(1, (monthly!$E$2:$E$5025=$L$30)* (monthly!$F$2:$F$5025=$I35), 0))} -> 1495 | M35: {=INDEX(monthly!$K$2:$K$5025, MATCH(1, (monthly!$E$2:$E$5025=$M$30)* (monthly!$F$2:$F$5025=$I35), 0))} -> 2326 | N35: =IFERROR((K35/L35)-1,0) -> -0.22608696 | O35: =IFERROR((K35/M35)-1,0) -> -0.50257954
A36: 406 | B36: Сири | C36: {=INDEX(monthly!$J$2:$J$5025, MATCH(1, (monthly!$E$2:$E$5025=$C$30)* (monthly!$F$2:$F$5025=$A36), 0))} -> 4457 | D36: {=INDEX(monthly!$J$2:$J$5025, MATCH(1, (monthly!$E$2:$E$5025=$D$30)* (monthly!$F$2:$F$5025=$A36), 0))} -> 4493 | E36: {=INDEX(monthly!$J$2:$J$5025, MATCH(1, (monthly!$E$2:$E$5025=$E$30)* (monthly!$F$2:$F$5025=$A36), 0))} -> 3610 | F36: =IFERROR((C36/D36)-1,0) -> -0.0080124638 | G36: =IFERROR((C36/E36)-1,0) -> 0.23462604 | I36: 406 | J36: Сири | K36: {=INDEX(monthly!$K$2:$K$5025, MATCH(1, (monthly!$E$2:$E$5025=$K$30)* (monthly!$F$2:$F$5025=$I36), 0))} -> 26123 | L36: {=INDEX(monthly!$K$2:$K$5025, MATCH(1, (monthly!$E$2:$E$5025=$L$30)* (monthly!$F$2:$F$5025=$I36), 0))} -> 25727 | M36: {=INDEX(monthly!$K$2:$K$5025, MATCH(1, (monthly!$E$2:$E$5025=$M$30)* (monthly!$F$2:$F$5025=$I36), 0))} -> 24122 | N36: =IFERROR((K36/L36)-1,0) -> 0.015392389 | O36: =IFERROR((K36/M36)-1,0) -> 0.082953321 | Q36: =(C36/C39)*100% -> 0.57243771
A37: 2105 | B37: Морозиво | C37: {=INDEX(monthly!$J$2:$J$5025, MATCH(1, (monthly!$E$2:$E$5025=$C$30)* (monthly!$F$2:$F$5025=$A37), 0))} -> 27 | D37: {=INDEX(monthly!$J$2:$J$5025, MATCH(1, (monthly!$E$2:$E$5025=$D$30)* (monthly!$F$2:$F$5025=$A37), 0))} -> 100 | E37: {=INDEX(monthly!$J$2:$J$5025, MATCH(1, (monthly!$E$2:$E$5025=$E$30)* (monthly!$F$2:$F$5025=$A37), 0))} -> 37 | F37: =IFERROR((C37/D37)-1,0) -> -0.73 | G37: =IFERROR((C37/E37)-1,0) -> -0.27027027 | I37: 2105 | J37: Морозиво | K37: {=INDEX(monthly!$K$2:$K$5025, MATCH(1, (monthly!$E$2:$E$5025=$K$30)* (monthly!$F$2:$F$5025=$I37), 0))} -> 128 | L37: {=INDEX(monthly!$K$2:$K$5025, MATCH(1, (monthly!$E$2:$E$5025=$L$30)* (monthly!$F$2:$F$5025=$I37), 0))} -> 337 | M37: {=INDEX(monthly!$K$2:$K$5025, MATCH(1, (monthly!$E$2:$E$5025=$M$30)* (monthly!$F$2:$F$5025=$I37), 0))} -> 184 | N37: =IFERROR((K37/L37)-1,0) -> -0.62017804 | O37: =IFERROR((K37/M37)-1,0) -> -0.30434783
A38: 3501 | B38: Казеїн | C38: {=INDEX(monthly!$J$2:$J$5025, MATCH(1, (monthly!$E$2:$E$5025=$C$30)* (monthly!$F$2:$F$5025=$A38), 0))} -> 1 | D38: {=INDEX(monthly!$J$2:$J$5025, MATCH(1, (monthly!$E$2:$E$5025=$D$30)* (monthly!$F$2:$F$5025=$A38), 0))} -> 10 | E38: {=INDEX(monthly!$J$2:$J$5025, MATCH(1, (monthly!$E$2:$E$5025=$E$30)* (monthly!$F$2:$F$5025=$A38), 0))} -> 3 | F38: =IFERROR((C38/D38)-1,0) -> -0.9 | G38: =IFERROR((C38/E38)-1,0) -> -0.66666667 | I38: 3501 | J38: Казеїн | K38: {=INDEX(monthly!$K$2:$K$5025, MATCH(1, (monthly!$E$2:$E$5025=$K$30)* (monthly!$F$2:$F$5025=$I38), 0))} -> 8 | L38: {=INDEX(monthly!$K$2:$K$5025, MATCH(1, (monthly!$E$2:$E$5025=$L$30)* (monthly!$F$2:$F$5025=$I38), 0))} -> 70 | M38: {=INDEX(monthly!$K$2:$K$5025, MATCH(1, (monthly!$E$2:$E$5025=$M$30)* (monthly!$F$2:$F$5025=$I38), 0))} -> 20 | N38: =IFERROR((K38/L38)-1,0) -> -0.88571429 | O38: =IFERROR((K38/M38)-1,0) -> -0.6
C39: =SUM(C31:C38) -> 7786 | D39: =SUM(D31:D38) -> 8236 | E39: =SUM(E31:E38) -> 6307 | F39: =IFERROR((C39/D39)-1,0) -> -0.054638174 | G39: =IFERROR((C39/E39)-1,0) -> 0.23450135 | K39: =SUM(K31:K38) -> 33289 | L39: =SUM(L31:L38) -> 33859 | M39: =SUM(M31:M38) -> 31757 | N39: =IFERROR((K39/L39)-1,0) -> -0.01683452 | O39: =IFERROR((K39/M39)-1,0) -> 0.048241333
B42: З поч. року | J42: З поч. року
B43: тонн | J43: тис. дол.
A44: Code | B44: Product | C44: =C$17 -> Січ.-вер. 2026 | D44: =D$17 -> Січ.-сер. 2026 | E44: =E$17 -> Січ.-вер. 2025 | F44: =G$3 -> 26/25 | H44: місяць | I44: Code | J44: Product | K44: =C$17 -> Січ.-вер. 2026 | L44: =D$17 -> Січ.-сер. 2026 | M44: =E$17 -> Січ.-вер. 2025 | N44: =G$3 -> 26/25 | P44: місяць | R44: Import share
A45: 401 | B45: Молоко та вершки, не згущені | C45: {=INDEX(period!$J$2:$J$5033, MATCH(1, (period!$E$2:$E$5033=$C$44)* (period!$F$2:$F$5033=$A45), 0))} -> 7765 | D45: {=INDEX(period!$J$2:$J$5033, MATCH(1, (period!$E$2:$E$5033=$D$44)* (period!$F$2:$F$5033=$A45), 0))} -> 6488 | E45: {=INDEX(period!$J$2:$J$5033, MATCH(1, (period!$E$2:$E$5033=$E$44)* (period!$F$2:$F$5033=$A45), 0))} -> 2317 | F45: =(C45/E45)-1 -> 2.3513164 | H45: =C45-D45 -> 1277 | I45: 401 | J45: Молоко та вершки, не згущені | K45: {=INDEX(period!$K$2:$K$5033, MATCH(1, (period!$E$2:$E$5033=$K$44)* (period!$F$2:$F$5033=$A45), 0))} -> 10174 | L45: {=INDEX(period!$K$2:$K$5033, MATCH(1, (period!$E$2:$E$5033=$L$44)* (period!$F$2:$F$5033=$A45), 0))} -> 8718 | M45: {=INDEX(period!$K$2:$K$5033, MATCH(1, (period!$E$2:$E$5033=$M$44)* (period!$F$2:$F$5033=$A45), 0))} -> 3644 | N45: =(K45/M45)-1 -> 1.7919868 | P45: =K45-L45 -> 1456 | Q45: Молоко та вершки, не згущені | R45: =C45/$C$53*100% -> 0.12134519
...

Sheet d1
A1: =dairy!$A3 -> Code | B1: =dairy!$B3 -> Product | C1: =dairy!$R3 -> Export share
A2: =dairy!$A4 -> 401 | B2: =dairy!$B4 -> Молоко та вершки, не згущені | C2: =dairy!$R4 -> 0.065167115
A3: =dairy!$A5 -> 402 | B3: =dairy!$B5 -> Молоко та вершки, згущені | C3: =dairy!$R5 -> 0.31180105
A4: =dairy!$A6 -> 403 | B4: =dairy!$B6 -> Кисломолочні продукти | C4: =dairy!$R6 -> 0.029431332
A5: =dairy!$A7 -> 404 | B5: =dairy!$B7 -> Молочна сироватка | C5: =dairy!$R7 -> 0.082591478
A6: =dairy!$A8 -> 405 | B6: =dairy!$B8 -> Масло вершкове | C6: =dairy!$R8 -> 0.12995406
A7: =dairy!$A9 -> 406 | B7: =dairy!$B9 -> Сири | C7: =dairy!$R9 -> 0.22968478
A8: =dairy!$A10 -> 2105 | B8: =dairy!$B10 -> Морозиво | C8: =dairy!$R10 -> 0.094440044
A9: =dairy!$A11 -> 3501 | B9: =dairy!$B11 -> Казеїн | C9: =dairy!$R11 -> 0.056930144

Sheet d2
A1: =dairy!$I3 -> Code | B1: =dairy!$J3 -> Product | C1: =dairy!$K3 -> 46266 | D1: =dairy!$L3 -> 46235 | E1: =dairy!$M3 -> 45901
A2: =dairy!$I4 -> 401 | B2: =dairy!$J4 -> Молоко та вершки, не згущені | C2: =dairy!$K4 -> 2057 | D2: =dairy!$L4 -> 1510 | E2: =dairy!$M4 -> 1709
A3: =dairy!$I5 -> 402 | B3: =dairy!$J5 -> Молоко та вершки, згущені | C3: =dairy!$K5 -> 9842 | D3: =dairy!$L5 -> 7759 | E3: =dairy!$M5 -> 4560
A4: =dairy!$I6 -> 403 | B4: =dairy!$J6 -> Кисломолочні продукти | C4: =dairy!$K6 -> 929 | D4: =dairy!$L6 -> 1073 | E4: =dairy!$M6 -> 936
A5: =dairy!$I7 -> 404 | B5: =dairy!$J7 -> Молочна сироватка | C5: =dairy!$K7 -> 2607 | D5: =dairy!$L7 -> 2241 | E5: =dairy!$M7 -> 1136
A6: =dairy!$I8 -> 405 | B6: =dairy!$J8 -> Масло вершкове | C6: =dairy!$K8 -> 4102 | D6: =dairy!$L8 -> 3270 | E6: =dairy!$M8 -> 6855
A7: =dairy!$I9 -> 406 | B7: =dairy!$J9 -> Сири | C7: =dairy!$K9 -> 7250 | D7: =dairy!$L9 -> 5246 | E7: =dairy!$M9 -> 5465
A8: =dairy!$I10 -> 2105 | B8: =dairy!$J10 -> Морозиво | C8: =dairy!$K10 -> 2981 | D8: =dairy!$L10 -> 7963 | E8: =dairy!$M10 -> 2601
A9: =dairy!$I11 -> 3501 | B9: =dairy!$J11 -> Казеїн | C9: =dairy!$K11 -> 1797 | D9: =dairy!$L11 -> 1456 | E9: =dairy!$M11 -> 1873

Sheet d3
A1: =dairy!$I30 -> Code | B1: =dairy!$J30 -> Product | C1: =dairy!$C3 -> 46266 | D1: =dairy!$L30 -> 46235 | E1: =dairy!$M30 -> 45901
A2: =dairy!$I31 -> 401 | B2: =dairy!$J31 -> Молоко та вершки, не згущені | C2: =dairy!$K31 -> 1456 | D2: =dairy!$L31 -> 1644 | E2: =dairy!$M31 -> 676
A3: =dairy!$I32 -> 402 | B3: =dairy!$J32 -> Молоко та вершки, згущені | C3: =dairy!$K32 -> 859 | D3: =dairy!$L32 -> 542 | E3: =dairy!$M32 -> 1198
A4: =dairy!$I33 -> 403 | B4: =dairy!$J33 -> Кисломолочні продукти | C4: =dairy!$K33 -> 2211 | D4: =dairy!$L33 -> 2182 | E4: =dairy!$M33 -> 1435
A5: =dairy!$I34 -> 404 | B5: =dairy!$J34 -> Молочна сироватка | C5: =dairy!$K34 -> 1347 | D5: =dairy!$L34 -> 1862 | E5: =dairy!$M34 -> 1796
A6: =dairy!$I35 -> 405 | B6: =dairy!$J35 -> Масло вершкове | C6: =dairy!$K35 -> 1157 | D6: =dairy!$L35 -> 1495 | E6: =dairy!$M35 -> 2326
A7: =dairy!$I36 -> 406 | B7: =dairy!$J36 -> Сири | C7: =dairy!$K36 -> 26123 | D7: =dairy!$L36 -> 25727 | E7: =dairy!$M36 -> 24122
A8: =dairy!$I37 -> 2105 | B8: =dairy!$J37 -> Морозиво | C8: =dairy!$K37 -> 128 | D8: =dairy!$L37 -> 337 | E8: =dairy!$M37 -> 184
A9: =dairy!$I38 -> 3501 | B9: =dairy!$J38 -> Казеїн | C9: =dairy!$K38 -> 8 | D9: =dairy!$L38 -> 70 | E9: =dairy!$M38 -> 20

Sheet cattle
B1: ЕКСПОРТ
B2: тонн | C2: поточна | D2: попередня | E2: мин. рік | J2: тис. дол.
A3: Code | B3: Product | C3: 46266 | D3: 46235 | E3: 45901 | F3: 26/26 | G3: 26/25 | I3: Code | J3: Product | K3: =C$3 -> 46266 | L3: =D$3 -> 46235 | M3: =E$3 -> 45901 | N3: =F$3 -> 26/26 | O3: =G$3 -> 26/25 | R3: Export share
A4: 102 | B4: ВРХ | C4: {=INDEX(monthly!$H$2:$H$5025, MATCH(1, (monthly!$E$2:$E$5025=$C$3)* (monthly!$F$2:$F$5025=$A4), 0))} -> 1172 | D4: {=INDEX(monthly!$H$2:$H$5025, MATCH(1, (monthly!$E$2:$E$5025=$D$3)* (monthly!$F$2:$F$5025=$A4), 0))} -> 1321 | E4: {=INDEX(monthly!$H$2:$H$5025, MATCH(1, (monthly!$E$2:$E$5025=$E$3)* (monthly!$F$2:$F$5025=$A4), 0))} -> 558 | F4: =(C4/D4)-1 -> -0.11279334 | G4: =(C4/E4)-1 -> 1.1003584 | I4: 102 | J4: ВРХ | K4: {=INDEX(monthly!$I$2:$I$5025, MATCH(1, (monthly!$E$2:$E$5025=$K$3)* (monthly!$F$2:$F$5025=$I4), 0))} -> 2935 | L4: {=INDEX(monthly!$I$2:$I$5025, MATCH(1, (monthly!$E$2:$E$5025=$L$3)* (monthly!$F$2:$F$5025=$I4), 0))} -> 3620 | M4: {=INDEX(monthly!$I$2:$I$5025, MATCH(1, (monthly!$E$2:$E$5025=$M$3)* (monthly!$F$2:$F$5025=$I4), 0))} -> 782 | N4: =(K4/L4)-1 -> -0.18922652 | O4: =(K4/M4)-1 -> 2.7531969 | Q4: ВРХ | R4: =K4/$K$7*100% -> 0.19735073
A5: 201 | B5: М'ясо ВРХ охолоджене | C5: {=INDEX(monthly!$H$2:$H$5025, MATCH(1, (monthly!$E$2:$E$5025=$C$3)* (monthly!$F$2:$F$5025=$A5), 0))} -> 515 | D5: {=INDEX(monthly!$H$2:$H$5025, MATCH(1, (monthly!$E$2:$E$5025=$D$3)* (monthly!$F$2:$F$5025=$A5), 0))} -> 474 | E5: {=INDEX(monthly!$H$2:$H$5025, MATCH(1, (monthly!$E$2:$E$5025=$E$3)* (monthly!$F$2:$F$5025=$A5), 0))} -> 104 | F5: =(C5/D5)-1 -> 0.08649789 | G5: =(C5/E5)-1 -> 3.9519231 | I5: 201 | J5: М'ясо ВРХ охолоджене | K5: {=INDEX(monthly!$I$2:$I$5025, MATCH(1, (monthly!$E$2:$E$5025=$K$3)* (monthly!$F$2:$F$5025=$I5), 0))} -> 4151 | L5: {=INDEX(monthly!$I$2:$I$5025, MATCH(1, (monthly!$E$2:$E$5025=$L$3)* (monthly!$F$2:$F$5025=$I5), 0))} -> 3959 | M5: {=INDEX(monthly!$I$2:$I$5025, MATCH(1, (monthly!$E$2:$E$5025=$M$3)* (monthly!$F$2:$F$5025=$I5), 0))} -> 621 | N5: =(K5/L5)-1 -> 0.048497095 | O5: =(K5/M5)-1 -> 5.68438 | Q5: М'ясо ВРХ охолоджене | R5: =K5/$K$7*100% -> 0.27911512
A6: 202 | B6: М'ясо ВРХ морожене | C6: {=INDEX(monthly!$H$2:$H$5025, MATCH(1, (monthly!$E$2:$E$5025=$C$3)* (monthly!$F$2:$F$5025=$A6), 0))} -> 1646 | D6: {=INDEX(monthly!$H$2:$H$5025, MATCH(1, (monthly!$E$2:$E$5025=$D$3)* (monthly!$F$2:$F$5025=$A6), 0))} -> 1820 | E6: {=INDEX(monthly!$H$2:$H$5025, MATCH(1, (monthly!$E$2:$E$5025=$E$3)* (monthly!$F$2:$F$5025=$A6), 0))} -> 1174 | F6: =(C6/D6)-1 -> -0.095604396 | G6: =(C6/E6)-1 -> 0.40204429 | I6: 202 | J6: М'ясо ВРХ морожене | K6: {=INDEX(monthly!$I$2:$I$5025, MATCH(1, (monthly!$E$2:$E$5025=$K$3)* (monthly!$F$2:$F$5025=$I6), 0))} -> 7786 | L6: {=INDEX(monthly!$I$2:$I$5025, MATCH(1, (monthly!$E$2:$E$5025=$L$3)* (monthly!$F$2:$F$5025=$I6), 0))} -> 8162 | M6: {=INDEX(monthly!$I$2:$I$5025, MATCH(1, (monthly!$E$2:$E$5025=$M$3)* (monthly!$F$2:$F$5025=$I6), 0))} -> 5451 | N6: =(K6/L6)-1 -> -0.04606714 | O6: =(K6/M6)-1 -> 0.42836177 | Q6: М'ясо ВРХ морожене | R6: =K6/$K$7*100% -> 0.52353416
C7: =SUM(C4:C6) -> 3333 | D7: =SUM(D4:D6) -> 3615 | E7: =SUM(E4:E6) -> 1836 | F7: =(C7/D7)-1 -> -0.078008299 | G7: =(C7/E7)-1 -> 0.81535948 | K7: =SUM(K4:K6) -> 14872 | L7: =SUM(L4:L6) -> 15741 | M7: =SUM(M4:M6) -> 6854 | N7: =(K7/L7)-1 -> -0.05520615 | O7: =(K7/M7)-1 -> 1.1698278 | R7: =SUM(R4:R6) -> 1
B10: З поч. року | J10: З поч. року | T10: 3620 | U10: 2935 | V10: =(U10/T10)-1 -> -0.18922652
B11: тонн | C11: поточна | D11: попередня | E11: мин. рік | J11: тис. дол.
A12: Code | B12: Product | C12: Січ.-вер. 2026 | D12: Січ.-сер. 2026 | E12: Січ.-вер. 2025 | F12: =G$3 -> 26/25 | H12: місяць | I12: Code | J12: Product | K12: =C$12 -> Січ.-вер. 2026 | L12: =D$12 -> Січ.-сер. 2026 | M12: =E$12 -> Січ.-вер. 2025 | N12: =G$3 -> 26/25 | P12: =H12 -> місяць
A13: 102 | B13: ВРХ | C13: {=INDEX(period!$H$2:$H$5033, MATCH(1, (period!$E$2:$E$5033=$C$12)* (period!$F$2:$F$5033=$A13), 0))} -> 14645 | D13: {=INDEX(period!$H$2:$H$5033, MATCH(1, (period!$E$2:$E$5033=$D$12)* (period!$F$2:$F$5033=$A13), 0))} -> 13473 | E13: {=INDEX(period!$H$2:$H$5033, MATCH(1, (period!$E$2:$E$5033=$E$12)* (period!$F$2:$F$5033=$A13), 0))} -> 13282 | F13: =(C13/E13)-1 -> 0.10262009 | H13: =C13-D13 -> 1172 | I13: 102 | J13: ВРХ | K13: {=INDEX(period!$I$2:$I$5033, MATCH(1, (period!$E$2:$E$5033=$K$12)* (period!$F$2:$F$5033=$I13), 0))} -> 35250 | L13: {=INDEX(period!$I$2:$I$5033, MATCH(1, (period!$E$2:$E$5033=$L$12)* (period!$F$2:$F$5033=$I13), 0))} -> 32315 | M13: {=INDEX(period!$I$2:$I$5033, MATCH(1, (period!$E$2:$E$5033=$M$12)* (period!$F$2:$F$5033=$I13), 0))} -> 29218 | N13: =(K13/M13)-1 -> 0.20644808 | P13: =K13-L13 -> 2935
A14: 201 | B14: М'ясо ВРХ охолоджене | C14: {=INDEX(period!$H$2:$H$5033, MATCH(1, (period!$E$2:$E$5033=$C$12)* (period!$F$2:$F$5033=$A14), 0))} -> 3557 | D14: {=INDEX(period!$H$2:$H$5033, MATCH(1, (period!$E$2:$E$5033=$D$12)* (period!$F$2:$F$5033=$A14), 0))} -> 3042 | E14: {=INDEX(period!$H$2:$H$5033, MATCH(1, (period!$E$2:$E$5033=$E$12)* (period!$F$2:$F$5033=$A14), 0))} -> 224 | F14: =(C14/E14)-1 -> 14.879464 | H14: =C14-D14 -> 515 | I14: 201 | J14: М'ясо ВРХ охолоджене | K14: {=INDEX(period!$I$2:$I$5033, MATCH(1, (period!$E$2:$E$5033=$K$12)* (period!$F$2:$F$5033=$I14), 0))} -> 28520 | L14: {=INDEX(period!$I$2:$I$5033, MATCH(1, (period!$E$2:$E$5033=$L$12)* (period!$F$2:$F$5033=$I14), 0))} -> 24369 | M14: {=INDEX(period!$I$2:$I$5033, MATCH(1, (period!$E$2:$E$5033=$M$12)* (period!$F$2:$F$5033=$I14), 0))} -> 1313 | N14: =(K14/M14)-1 -> 20.721249 | P14: =K14-L14 -> 4151
A15: 202 | B15: М'ясо ВРХ морожене | C15: {=INDEX(period!$H$2:$H$5033, MATCH(1, (period!$E$2:$E$5033=$C$12)* (period!$F$2:$F$5033=$A15), 0))} -> 14398 | D15: {=INDEX(period!$H$2:$H$5033, MATCH(1, (period!$E$2:$E$5033=$D$12)* (period!$F$2:$F$5033=$A15), 0))} -> 12752 | E15: {=INDEX(period!$H$2:$H$5033, MATCH(1, (period!$E$2:$E$5033=$E$12)* (period!$F$2:$F$5033=$A15), 0))} -> 13805 | F15: =(C15/E15)-1 -> 0.042955451 | H15: =C15-D15 -> 1646 | I15: 202 | J15: М'ясо ВРХ морожене | K15: {=INDEX(period!$I$2:$I$5033, MATCH(1, (period!$E$2:$E$5033=$K$12)* (period!$F$2:$F$5033=$I15), 0))} -> 65355 | L15: {=INDEX(period!$I$2:$I$5033, MATCH(1, (period!$E$2:$E$5033=$L$12)* (period!$F$2:$F$5033=$I15), 0))} -> 57569 | M15: {=INDEX(period!$I$2:$I$5033, MATCH(1, (period!$E$2:$E$5033=$M$12)* (period!$F$2:$F$5033=$I15), 0))} -> 56788 | N15: =(K15/M15)-1 -> 0.15085934 | P15: =K15-L15 -> 7786
C16: =SUM(C13:C15) -> 32600 | D16: =SUM(D13:D15) -> 29267 | E16: =SUM(E13:E15) -> 27311 | F16: =(C16/E16)-1 -> 0.19365823 | K16: =SUM(K13:K15) -> 129125 | L16: =SUM(L13:L15) -> 114253 | M16: =SUM(M13:M15) -> 87319 | N16: =(K16/M16)-1 -> 0.47877323
B18: ІМПОРТ
B19: тонн | J19: тис. дол.
A20: Code | B20: Product | C20: =C$3 -> 46266 | D20: =D$3 -> 46235 | E20: =E$3 -> 45901 | F20: =F$3 -> 26/26 | G20: =G$3 -> 26/25 | I20: Code | J20: Product | K20: =C$3 -> 46266 | L20: =D$3 -> 46235 | M20: =E$3 -> 45901 | N20: =F$3 -> 26/26 | O20: =G$3 -> 26/25 | R20: Import share
A21: 102 | B21: ВРХ | C21: {=INDEX(monthly!$J$2:$J$5025, MATCH(1, (monthly!$E$2:$E$5025=$C$20)* (monthly!$F$2:$F$5025=$A21), 0))} -> 0 | D21: {=INDEX(monthly!$J$2:$J$5025, MATCH(1, (monthly!$E$2:$E$5025=$D$20)* (monthly!$F$2:$F$5025=$A21), 0))} -> 0 | E21: {=INDEX(monthly!$J$2:$J$5025, MATCH(1, (monthly!$E$2:$E$5025=$E$20)* (monthly!$F$2:$F$5025=$A21), 0))} -> 0 | F21: =IFERROR((C21/D21)-1,0) -> 0 | G21: =IFERROR((C21/E21)-1,0) -> 0 | I21: 102 | J21: ВРХ | K21: {=INDEX(monthly!$K$2:$K$5025, MATCH(1, (monthly!$E$2:$E$5025=$K$20)* (monthly!$F$2:$F$5025=$I21), 0))} -> 0 | L21: {=INDEX(monthly!$K$2:$K$5025, MATCH(1, (monthly!$E$2:$E$5025=$L$20)* (monthly!$F$2:$F$5025=$I21), 0))} -> 0 | M21: {=INDEX(monthly!$K$2:$K$5025, MATCH(1, (monthly!$E$2:$E$5025=$M$20)* (monthly!$F$2:$F$5025=$I21), 0))} -> 0 | N21: =IFERROR((K21/L21)-1," ") | O21: =IFERROR((K21/M21)-1," ") | Q21: ВРХ | R21: =K21/$K$24*100% -> 0
A22: 201 | B22: М'ясо ВРХ охолоджене | C22: {=INDEX(monthly!$J$2:$J$5025, MATCH(1, (monthly!$E$2:$E$5025=$C$20)* (monthly!$F$2:$F$5025=$A22), 0))} -> 20 | D22: {=INDEX(monthly!$J$2:$J$5025, MATCH(1, (monthly!$E$2:$E$5025=$D$20)* (monthly!$F$2:$F$5025=$A22), 0))} -> 9 | E22: {=INDEX(monthly!$J$2:$J$5025, MATCH(1, (monthly!$E$2:$E$5025=$E$20)* (monthly!$F$2:$F$5025=$A22), 0))} -> 11 | F22: =IFERROR((C22/D22)-1,0) -> 1.2222222 | G22: =IFERROR((C22/E22)-1,0) -> 0.81818182 | I22: 201 | J22: М'ясо ВРХ охолоджене | K22: {=INDEX(monthly!$K$2:$K$5025, MATCH(1, (monthly!$E$2:$E$5025=$K$20)* (monthly!$F$2:$F$5025=$I22), 0))} -> 636 | L22: {=INDEX(monthly!$K$2:$K$5025, MATCH(1, (monthly!$E$2:$E$5025=$L$20)* (monthly!$F$2:$F$5025=$I22), 0))} -> 167 | M22: {=INDEX(monthly!$K$2:$K$5025, MATCH(1, (monthly!$E$2:$E$5025=$M$20)* (monthly!$F$2:$F$5025=$I22), 0))} -> 203 | N22: =(K22/L22)-1 -> 2.8083832 | O22: =(K22/M22)-1 -> 2.1330049 | Q22: М'ясо ВРХ охолоджене | R22: =K22/$K$24*100% -> 0.33211488
A23: 202 | B23: М'ясо ВРХ морожене | C23: {=INDEX(monthly!$J$2:$J$5025, MATCH(1, (monthly!$E$2:$E$5025=$C$20)* (monthly!$F$2:$F$5025=$A23), 0))} -> 186 | D23: {=INDEX(monthly!$J$2:$J$5025, MATCH(1, (monthly!$E$2:$E$5025=$D$20)* (monthly!$F$2:$F$5025=$A23), 0))} -> 84 | E23: {=INDEX(monthly!$J$2:$J$5025, MATCH(1, (monthly!$E$2:$E$5025=$E$20)* (monthly!$F$2:$F$5025=$A23), 0))} -> 72 | F23: =IFERROR((C23/D23)-1,0) -> 1.2142857 | G23: =IFERROR((C23/E23)-1,0) -> 1.5833333 | I23: 202 | J23: М'ясо ВРХ морожене | K23: {=INDEX(monthly!$K$2:$K$5025, MATCH(1, (monthly!$E$2:$E$5025=$K$20)* (monthly!$F$2:$F$5025=$I23), 0))} -> 1279 | L23: {=INDEX(monthly!$K$2:$K$5025, MATCH(1, (monthly!$E$2:$E$5025=$L$20)* (monthly!$F$2:$F$5025=$I23), 0))} -> 619 | M23: {=INDEX(monthly!$K$2:$K$5025, MATCH(1, (monthly!$E$2:$E$5025=$M$20)* (monthly!$F$2:$F$5025=$I23), 0))} -> 676 | N23: =(K23/L23)-1 -> 1.0662359 | O23: =(K23/M23)-1 -> 0.89201183 | Q23: М'ясо ВРХ морожене | R23: =K23/$K$24*100% -> 0.66788512
C24: =SUM(C21:C23) -> 206 | D24: =SUM(D21:D23) -> 93 | E24: =SUM(E21:E23) -> 83 | F24: =IFERROR((C24/D24)-1,0) -> 1.2150538 | G24: =IFERROR((C24/E24)-1,0) -> 1.4819277 | K24: =SUM(K21:K23) -> 1915 | L24: =SUM(L21:L23) -> 786 | M24: =SUM(M21:M23) -> 879 | N24: =(K24/L24)-1 -> 1.4363868 | O24: =(K24/M24)-1 -> 1.1786121 | R24: =SUM(R21:R23) -> 1
B27: З поч. року | J27: З поч. року
B28: тонн | J28: тис. дол.
A29: Code | B29: Product | C29: =C$12 -> Січ.-вер. 2026 | D29: =D$12 -> Січ.-сер. 2026 | E29: =E$12 -> Січ.-вер. 2025 | F29: =G$3 -> 26/25 | H29: =H12 -> місяць | I29: Code | J29: Product | K29: =C$12 -> Січ.-вер. 2026 | L29: =D$12 -> Січ.-сер. 2026 | M29: =E$12 -> Січ.-вер. 2025 | N29: =G$3 -> 26/25 | P29: =H12 -> місяць
A30: 102 | B30: ВРХ | C30: {=INDEX(period!$J$2:$J$5033, MATCH(1, (period!$E$2:$E$5033=$C$29)* (period!$F$2:$F$5033=$A30), 0))} -> 93 | D30: {=INDEX(period!$J$2:$J$5033, MATCH(1, (period!$E$2:$E$5033=$D$29)* (period!$F$2:$F$5033=$A30), 0))} -> 93 | E30: {=INDEX(period!$J$2:$J$5033, MATCH(1, (period!$E$2:$E$5033=$E$29)* (period!$F$2:$F$5033=$A30), 0))} -> 512 | F30: =(C30/E30)-1 -> -0.81835938 | H30: =C30-D30 -> 0 | I30: 102 | J30: ВРХ | K30: {=INDEX(period!$K$2:$K$5033, MATCH(1, (period!$E$2:$E$5033=$K$29)* (period!$F$2:$F$5033=$I30), 0))} -> 865 | L30: {=INDEX(period!$K$2:$K$5033, MATCH(1, (period!$E$2:$E$5033=$L$29)* (period!$F$2:$F$5033=$I30), 0))} -> 865 | M30: {=INDEX(period!$K$2:$K$5033, MATCH(1, (period!$E$2:$E$5033=$M$29)* (period!$F$2:$F$5033=$I30), 0))} -> 3952 | N30: =(K30/M30)-1 -> -0.78112348 | P30: =K30-L30 -> 0 | T30: 5676
A31: 201 | B31: М'ясо ВРХ охолоджене | C31: {=INDEX(period!$J$2:$J$5033, MATCH(1, (period!$E$2:$E$5033=$C$29)* (period!$F$2:$F$5033=$A31), 0))} -> 119 | D31: {=INDEX(period!$J$2:$J$5033, MATCH(1, (period!$E$2:$E$5033=$D$29)* (period!$F$2:$F$5033=$A31), 0))} -> 99 | E31: {=INDEX(period!$J$2:$J$5033, MATCH(1, (period!$E$2:$E$5033=$E$29)* (period!$F$2:$F$5033=$A31), 0))} -> 106 | F31: =(C31/E31)-1 -> 0.12264151 | H31: =C31-D31 -> 20 | I31: 201 | J31: М'ясо ВРХ охолоджене | K31: {=INDEX(period!$K$2:$K$5033, MATCH(1, (period!$E$2:$E$5033=$K$29)* (period!$F$2:$F$5033=$I31), 0))} -> 3379 | L31: {=INDEX(period!$K$2:$K$5033, MATCH(1, (period!$E$2:$E$5033=$L$29)* (period!$F$2:$F$5033=$I31), 0))} -> 2743 | M31: {=INDEX(period!$K$2:$K$5033, MATCH(1, (period!$E$2:$E$5033=$M$29)* (period!$F$2:$F$5033=$I31), 0))} -> 2445 | N31: =(K31/M31)-1 -> 0.38200409 | P31: =K31-L31 -> 636 | T31: 4689
A32: 202 | B32: М'ясо ВРХ морожене | C32: {=INDEX(period!$J$2:$J$5033, MATCH(1, (period!$E$2:$E$5033=$C$29)* (period!$F$2:$F$5033=$A32), 0))} -> 940 | D32: {=INDEX(period!$J$2:$J$5033, MATCH(1, (period!$E$2:$E$5033=$D$29)* (period!$F$2:$F$5033=$A32), 0))} -> 754 | E32: {=INDEX(period!$J$2:$J$5033, MATCH(1, (period!$E$2:$E$5033=$E$29)* (period!$F$2:$F$5033=$A32), 0))} -> 1074 | F32: =(C32/E32)-1 -> -0.12476723 | H32: =C32-D32 -> 186 | I32: 202 | J32: М'ясо ВРХ морожене | K32: {=INDEX(period!$K$2:$K$5033, MATCH(1, (period!$E$2:$E$5033=$K$29)* (period!$F$2:$F$5033=$I32), 0))} -> 7060 | L32: {=INDEX(period!$K$2:$K$5033, MATCH(1, (period!$E$2:$E$5033=$L$29)* (period!$F$2:$F$5033=$I32), 0))} -> 5781 | M32: {=INDEX(period!$K$2:$K$5033, MATCH(1, (period!$E$2:$E$5033=$M$29)* (period!$F$2:$F$5033=$I32), 0))} -> 8194 | N32: =(K32/M32)-1 -> -0.13839395 | P32: =K32-L32 -> 1279 | T32: 3861
C33: =SUM(C30:C32) -> 1152 | D33: =SUM(D30:D32) -> 946 | E33: =SUM(E30:E32) -> 1692 | F33: =(C33/E33)-1 -> -0.31914894 | K33: =SUM(K30:K32) -> 11304 | L33: =SUM(L30:L32) -> 9389 | M33: =SUM(M30:M32) -> 14591 | N33: =(K33/M33)-1 -> -0.22527585
T34: =T30-T31 -> 987
J35: сальдо місяць | K35: =K7-K24 -> 12957 | T35: =T31-T32 -> 828
J37: сальдо рік | K37: =K16-K33 -> 117821

Sheet d4
A1: =cattle!$A3 -> Code | B1: =cattle!$B3 -> Product | C1: =cattle!$R3 -> Export share
A2: =cattle!$A4 -> 102 | B2: =cattle!$B4 -> ВРХ | C2: =cattle!$R4 -> 0.19735073
A3: =cattle!$A5 -> 201 | B3: =cattle!$B5 -> М'ясо ВРХ охолоджене | C3: =cattle!$R5 -> 0.27911512
A4: =cattle!$A6 -> 202 | B4: =cattle!$B6 -> М'ясо ВРХ морожене | C4: =cattle!$R6 -> 0.52353416

Sheet d5
A1: =cattle!$I3 -> Code | B1: =cattle!$J3 -> Product | C1: =cattle!$K3 -> 46266 | D1: =cattle!$L3 -> 46235 | E1: =cattle!$M3 -> 45901
A2: =cattle!$I4 -> 102 | B2: =cattle!$J4 -> ВРХ | C2: =cattle!$K4 -> 2935 | D2: =cattle!$L4 -> 3620 | E2: =cattle!$M4 -> 782
A3: =cattle!$I5 -> 201 | B3: =cattle!$J5 -> М'ясо ВРХ охолоджене | C3: =cattle!$K5 -> 4151 | D3: =cattle!$L5 -> 3959 | E3: =cattle!$M5 -> 621
A4: =cattle!$I6 -> 202 | B4: =cattle!$J6 -> М'ясо ВРХ морожене | C4: =cattle!$K6 -> 7786 | D4: =cattle!$L6 -> 8162 | E4: =cattle!$M6 -> 5451

Sheet d6
A1: =cattle!$I20 -> Code | B1: =cattle!$J20 -> Product | C1: =cattle!$K20 -> 46266 | D1: =cattle!$L20 -> 46235 | E1: =cattle!$M20 -> 45901
A2: =cattle!$I21 -> 102 | B2: =cattle!$J21 -> ВРХ | C2: =cattle!$K21 -> 0 | D2: =cattle!$L21 -> 0 | E2: =cattle!$M21 -> 0
A3: =cattle!$I22 -> 201 | B3: =cattle!$J22 -> М'ясо ВРХ охолоджене | C3: =cattle!$K22 -> 636 | D3: =cattle!$L22 -> 167 | E3: =cattle!$M22 -> 203
A4: =cattle!$I23 -> 202 | B4: =cattle!$J23 -> М'ясо ВРХ морожене | C4: =cattle!$K23 -> 1279 | D4: =cattle!$L23 -> 619 | E4: =cattle!$M23 -> 676

Sheet set
A1: ="Січ.-"& CHOOSE(MOD(ROW()-ROW($A$1),12)+1, "січ.","лют.","бер.","кві.","тра.","чер.", "лип.","сер.","вер.","жов.","лис.","гру.") &" "&(2024+INT((ROW()-ROW($A$1))/12)) -> Січ.-січ. 2024 | B1: 45292
A2: ="Січ.-"& CHOOSE(MOD(ROW()-ROW($A$1),12)+1, "січ.","лют.","бер.","кві.","тра.","чер.", "лип.","сер.","вер.","жов.","лис.","гру.") &" "&(2024+INT((ROW()-ROW($A$1))/12)) -> Січ.-лют. 2024 | B2: 45323
A3: ="Січ.-"& CHOOSE(MOD(ROW()-ROW($A$1),12)+1, "січ.","лют.","бер.","кві.","тра.","чер.", "лип.","сер.","вер.","жов.","лис.","гру.") &" "&(2024+INT((ROW()-ROW($A$1))/12)) -> Січ.-бер. 2024 | B3: 45352
A4: ="Січ.-"& CHOOSE(MOD(ROW()-ROW($A$1),12)+1, "січ.","лют.","бер.","кві.","тра.","чер.", "лип.","сер.","вер.","жов.","лис.","гру.") &" "&(2024+INT((ROW()-ROW($A$1))/12)) -> Січ.-кві. 2024 | B4: 45383
A5: ="Січ.-"& CHOOSE(MOD(ROW()-ROW($A$1),12)+1, "січ.","лют.","бер.","кві.","тра.","чер.", "лип.","сер.","вер.","жов.","лис.","гру.") &" "&(2024+INT((ROW()-ROW($A$1))/12)) -> Січ.-тра. 2024 | B5: 45413
A6: ="Січ.-"& CHOOSE(MOD(ROW()-ROW($A$1),12)+1, "січ.","лют.","бер.","кві.","тра.","чер.", "лип.","сер.","вер.","жов.","лис.","гру.") &" "&(2024+INT((ROW()-ROW($A$1))/12)) -> Січ.-чер. 2024 | B6: 45444
A7: ="Січ.-"& CHOOSE(MOD(ROW()-ROW($A$1),12)+1, "січ.","лют.","бер.","кві.","тра.","чер.", "лип.","сер.","вер.","жов.","лис.","гру.") &" "&(2024+INT((ROW()-ROW($A$1))/12)) -> Січ.-лип. 2024 | B7: 45474
A8: ="Січ.-"& CHOOSE(MOD(ROW()-ROW($A$1),12)+1, "січ.","лют.","бер.","кві.","тра.","чер.", "лип.","сер.","вер.","жов.","лис.","гру.") &" "&(2024+INT((ROW()-ROW($A$1))/12)) -> Січ.-сер. 2024 | B8: 45505
A9: ="Січ.-"& CHOOSE(MOD(ROW()-ROW($A$1),12)+1, "січ.","лют.","бер.","кві.","тра.","чер.", "лип.","сер.","вер.","жов.","лис.","гру.") &" "&(2024+INT((ROW()-ROW($A$1))/12)) -> Січ.-вер. 2024 | B9: 45536
A10: ="Січ.-"& CHOOSE(MOD(ROW()-ROW($A$1),12)+1, "січ.","лют.","бер.","кві.","тра.","чер.", "лип.","сер.","вер.","жов.","лис.","гру.") &" "&(2024+INT((ROW()-ROW($A$1))/12)) -> Січ.-жов. 2024 | B10: 45566
A11: ="Січ.-"& CHOOSE(MOD(ROW()-ROW($A$1),12)+1, "січ.","лют.","бер.","кві.","тра.","чер.", "лип.","сер.","вер.","жов.","лис.","гру.") &" "&(2024+INT((ROW()-ROW($A$1))/12)) -> Січ.-лис. 2024 | B11: 45597
A12: ="Січ.-"& CHOOSE(MOD(ROW()-ROW($A$1),12)+1, "січ.","лют.","бер.","кві.","тра.","чер.", "лип.","сер.","вер.","жов.","лис.","гру.") &" "&(2024+INT((ROW()-ROW($A$1))/12)) -> Січ.-гру. 2024 | B12: 45627
... A36: ="Січ.-"& CHOOSE(MOD(ROW()-ROW($A$1),12)+1, "січ.","лют.","бер.","кві.","тра.","чер.", "лип.","сер.","вер.","жов.","лис.","гру.") &" "&(2024+INT((ROW()-ROW($A$1))/12)) -> Січ.-гру. 2026 | B36: 46357
